<?xml version="1.0" encoding="utf-8"?>
<!-- This URDF was automatically created by SolidWorks to URDF Exporter! Originally created by Stephen Brawner (brawner@gmail.com) 
     Commit Version: 1.6.0-4-g7f85cfe  Build Version: 1.6.7995.38578
     For more information, please see http://wiki.ros.org/sw_urdf_exporter -->
<robot
  name="aws_amr_description">
  <link
    name="basefootprint_link">
    <inertial>
      <origin
        xyz="0 1.11022302462516E-16 -0.0165"
        rpy="0 0 0" />
      <mass
        value="40.12833" />
      <inertia
        ixx="2.41961604813898"
        ixy="0.00979349757253783"
        ixz="-3.46348297131225E-19"
        iyy="1.29747784781603"
        iyz="2.94246210047988E-16"
        izz="3.70981060406001" />
    </inertial>
    <visual>
      <origin
        xyz="0 0 0"
        rpy="0 0 0" />
      <geometry>
        <mesh
          filename="package://aws_amr_description/meshes/basefootprint_link.STL" />
      </geometry>
      <material
        name="">
        <color
          rgba="0.988235294117647 0.984313725490196 1 1" />
      </material>
    </visual>
    <collision>
      <origin
        xyz="0 0 0"
        rpy="0 0 0" />
      <geometry>
        <mesh
          filename="package://aws_amr_description/meshes/basefootprint_link.STL" />
      </geometry>
    </collision>
  </link>
  <link
    name="base_link">
    <inertial>
      <origin
        xyz="-0.00164219166089963 -0.0361894519725366 0.582086232959336"
        rpy="0 0 0" />
      <mass
        value="38.5841907210089" />
      <inertia
        ixx="1.94197264059665"
        ixy="0.00713596425149988"
        ixz="-0.000642438598698677"
        iyy="1.12447543859211"
        iyz="0.0721839356855261"
        izz="2.71974540999521" />
    </inertial>
    <visual>
      <origin
        xyz="0 0 0"
        rpy="0 0 0" />
      <geometry>
        <mesh
          filename="package://aws_amr_description/meshes/base_link.STL" />
      </geometry>
      <material
        name="">
        <color
          rgba="0.792156862745098 0.819607843137255 0.933333333333333 1" />
      </material>
    </visual>
    <collision>
      <origin
        xyz="0 0 0"
        rpy="0 0 0" />
      <geometry>
        <mesh
          filename="package://aws_amr_description/meshes/base_link.STL" />
      </geometry>
    </collision>
  </link>
  <joint
    name="base_joint"
    type="fixed">
    <origin
      xyz="0.000899965730756125 0 0.0898937183015765"
      rpy="0 0 0" />
    <parent
      link="basefootprint_link" />
    <child
      link="base_link" />
    <axis
      xyz="0 0 0" />
  </joint>
  <link
    name="FL_steering_link">
    <inertial>
      <origin
        xyz="-0.0475735313962515 0.00186107687732506 -0.0677613689716041"
        rpy="0 0 0" />
      <mass
        value="0.215025529188031" />
      <inertia
        ixx="0.000198183542170155"
        ixy="-1.33497937261361E-05"
        ixz="-3.32629600070803E-05"
        iyy="0.00019959509116102"
        iyz="-2.846870528717E-05"
        izz="0.000169543009769995" />
    </inertial>
    <visual>
      <origin
        xyz="0 0 0"
        rpy="0 0 0" />
      <geometry>
        <mesh
          filename="package://aws_amr_description/meshes/FL_steering_link.STL" />
      </geometry>
      <material
        name="">
        <color
          rgba="0.792156862745098 0.819607843137255 0.933333333333333 1" />
      </material>
    </visual>
    <collision>
      <origin
        xyz="0 0 0"
        rpy="0 0 0" />
      <geometry>
        <mesh
          filename="package://aws_amr_description/meshes/FL_steering_link.STL" />
      </geometry>
    </collision>
  </link>
  <joint
    name="FL_steering_joint"
    type="continuous">
    <origin
      xyz="0.241621591099171 -0.287902443050945 0.1095"
      rpy="0 0 0" />
    <parent
      link="base_link" />
    <child
      link="FL_steering_link" />
    <axis
      xyz="0 0 1" />
  </joint>
  <link
    name="FL_wheel">
    <inertial>
      <origin
        xyz="-6.33164459196145E-07 7.24319215598956E-06 0.0298545011765308"
        rpy="0 0 0" />
      <mass
        value="0.958024018560995" />
      <inertia
        ixx="0.00158537287142924"
        ixy="-2.95846442369442E-09"
        ixz="-3.34102631098615E-08"
        iyy="0.00158540670170445"
        iyz="3.81832211653294E-07"
        izz="0.00270273979063561" />
    </inertial>
    <visual>
      <origin
        xyz="0 0 0"
        rpy="0 0 0" />
      <geometry>
        <mesh
          filename="package://aws_amr_description/meshes/FL_wheel.STL" />
      </geometry>
      <material
        name="">
        <color
          rgba="0.792156862745098 0.819607843137255 0.933333333333333 1" />
      </material>
    </visual>
    <collision>
      <origin
        xyz="0 0 0"
        rpy="0 0 0" />
      <geometry>
        <mesh
          filename="package://aws_amr_description/meshes/FL_wheel.STL" />
      </geometry>
    </collision>
  </link>
  <joint
    name="FL_wheel_joint"
    type="continuous">
    <origin
      xyz="-0.0305911790614908 -0.00114332801035 -0.120198042415907"
      rpy="-1.5707963267949 0 -1.56206968053491" />
    <parent
      link="FL_steering_link" />
    <child
      link="FL_wheel" />
    <axis
      xyz="0 0 1" />
  </joint>
  <link
    name="FR_steering_link">
    <inertial>
      <origin
        xyz="0.0475274478951574 0.00285182033246123 -0.0677612853324359"
        rpy="0 0 0" />
      <mass
        value="0.21502552911799" />
      <inertia
        ixx="0.000197663290712632"
        ixy="1.32880364690958E-05"
        ixz="3.38130987976626E-05"
        iyy="0.000200115479651007"
        iyz="-2.78645224586072E-05"
        izz="0.000169542872766259" />
    </inertial>
    <visual>
      <origin
        xyz="0 0 0"
        rpy="0 0 0" />
      <geometry>
        <mesh
          filename="package://aws_amr_description/meshes/FR_steering_link.STL" />
      </geometry>
      <material
        name="">
        <color
          rgba="0.792156862745098 0.819607843137255 0.933333333333333 1" />
      </material>
    </visual>
    <collision>
      <origin
        xyz="0 0 0"
        rpy="0 0 0" />
      <geometry>
        <mesh
          filename="package://aws_amr_description/meshes/FR_steering_link.STL" />
      </geometry>
    </collision>
  </link>
  <joint
    name="FR_steering_joint"
    type="continuous">
    <origin
      xyz="-0.238360131971625 -0.292091180090165 0.1095"
      rpy="0 0 0" />
    <parent
      link="base_link" />
    <child
      link="FR_steering_link" />
    <axis
      xyz="0 0 1" />
  </joint>
  <link
    name="FR_wheel">
    <inertial>
      <origin
        xyz="5.20650804314293E-06 -5.07658490336849E-06 -0.0298545023400815"
        rpy="0 0 0" />
      <mass
        value="0.958024049096675" />
      <inertia
        ixx="0.00158539024593013"
        ixy="-1.71905301382618E-08"
        ixz="-2.74449388424433E-07"
        iyy="0.00158538938818371"
        iyz="2.67521391906746E-07"
        izz="0.00270273993089456" />
    </inertial>
    <visual>
      <origin
        xyz="0 0 0"
        rpy="0 0 0" />
      <geometry>
        <mesh
          filename="package://aws_amr_description/meshes/FR_wheel.STL" />
      </geometry>
      <material
        name="">
        <color
          rgba="0.792156862745098 0.819607843137255 0.933333333333333 1" />
      </material>
    </visual>
    <collision>
      <origin
        xyz="0 0 0"
        rpy="0 0 0" />
      <geometry>
        <mesh
          filename="package://aws_amr_description/meshes/FR_wheel.STL" />
      </geometry>
    </collision>
  </link>
  <joint
    name="FR_wheel_joint"
    type="continuous">
    <origin
      xyz="0.0306076729379445 -0.000545703798077279 -0.120198042415904"
      rpy="-1.57079632679489 0 -1.55999302446283" />
    <parent
      link="FR_steering_link" />
    <child
      link="FR_wheel" />
    <axis
      xyz="0 0 -1" />
  </joint>
  <link
    name="RL_steering_link">
    <inertial>
      <origin
        xyz="-0.0464294552503575 -0.0105497331235309 -0.0677612873166716"
        rpy="0 0 0" />
      <mass
        value="0.215025508213933" />
      <inertia
        ixx="0.000193460203508138"
        ixy="1.21901333978236E-05"
        ixz="-3.78976325309017E-05"
        iyy="0.000204318564874202"
        iyz="2.19892428029692E-05"
        izz="0.000169542871278703" />
    </inertial>
    <visual>
      <origin
        xyz="0 0 0"
        rpy="0 0 0" />
      <geometry>
        <mesh
          filename="package://aws_amr_description/meshes/RL_steering_link.STL" />
      </geometry>
      <material
        name="">
        <color
          rgba="0.792156862745098 0.819607843137255 0.933333333333333 1" />
      </material>
    </visual>
    <collision>
      <origin
        xyz="0 0 0"
        rpy="0 0 0" />
      <geometry>
        <mesh
          filename="package://aws_amr_description/meshes/RL_steering_link.STL" />
      </geometry>
    </collision>
  </link>
  <joint
    name="RL_steering_joint"
    type="continuous">
    <origin
      xyz="0.236560200510107 0.292075472326287 0.109500000000001"
      rpy="0 0 0" />
    <parent
      link="base_link" />
    <child
      link="RL_steering_link" />
    <axis
      xyz="0 0 1" />
  </joint>
  <link
    name="RL_wheel">
    <inertial>
      <origin
        xyz="7.27595754390631E-06 -5.91239966013513E-08 0.029854497682601"
        rpy="0 0 0" />
      <mass
        value="0.95802404699446" />
      <inertia
        ixx="0.00158540688618798"
        ixy="-1.99483853621513E-10"
        ixz="3.83119294653975E-07"
        iyy="0.00158537275280386"
        iyz="-3.17710383360308E-09"
        izz="0.00270274001401906" />
    </inertial>
    <visual>
      <origin
        xyz="0 0 0"
        rpy="0 0 0" />
      <geometry>
        <mesh
          filename="package://aws_amr_description/meshes/RL_wheel.STL" />
      </geometry>
      <material
        name="">
        <color
          rgba="0.792156862745098 0.819607843137255 0.933333333333333 1" />
      </material>
    </visual>
    <collision>
      <origin
        xyz="0 0 0"
        rpy="0 0 0" />
      <geometry>
        <mesh
          filename="package://aws_amr_description/meshes/RL_wheel.STL" />
      </geometry>
    </collision>
  </link>
  <joint
    name="RL_wheel_joint"
    type="continuous">
    <origin
      xyz="-0.0302883236333389 -0.00444352189074265 -0.120198042415911"
      rpy="-1.5707963267949 0 -1.39649764849145" />
    <parent
      link="RL_steering_link" />
    <child
      link="RL_wheel" />
    <axis
      xyz="0 0 1" />
  </joint>
  <link
    name="RR_steering_link">
    <inertial>
      <origin
        xyz="0.0472495916245045 -0.00584638955510888 -0.0677613703800073"
        rpy="0 0 0" />
      <mass
        value="0.215025525294734" />
      <inertia
        ixx="0.000195961020339611"
        ixy="-1.30437868222828E-05"
        ixz="3.55344485257814E-05"
        iyy="0.000201817609859164"
        iyz="2.55772259404588E-05"
        izz="0.000169543008646994" />
    </inertial>
    <visual>
      <origin
        xyz="0 0 0"
        rpy="0 0 0" />
      <geometry>
        <mesh
          filename="package://aws_amr_description/meshes/RR_steering_link.STL" />
      </geometry>
      <material
        name="">
        <color
          rgba="0.792156862745098 0.819607843137255 0.933333333333333 1" />
      </material>
    </visual>
    <collision>
      <origin
        xyz="0 0 0"
        rpy="0 0 0" />
      <geometry>
        <mesh
          filename="package://aws_amr_description/meshes/RR_steering_link.STL" />
      </geometry>
    </collision>
  </link>
  <joint
    name="RR_steering_joint"
    type="continuous">
    <origin
      xyz="-0.24342152256069 0.287886735287059 0.109500000000002"
      rpy="0 0 0" />
    <parent
      link="base_link" />
    <child
      link="RR_steering_link" />
    <axis
      xyz="0 0 1" />
  </joint>
  <link
    name="RR_wheel">
    <inertial>
      <origin
        xyz="-7.21200724410065E-06 -9.69764137839779E-07 -0.0298544968118679"
        rpy="0 0 0" />
      <mass
        value="0.958024083703301" />
      <inertia
        ixx="0.00158540647521623"
        ixy="4.52995256026229E-09"
        ixz="3.7968612593469E-07"
        iyy="0.00158537328067226"
        iyz="5.0927528925523E-08"
        izz="0.00270274017042597" />
    </inertial>
    <visual>
      <origin
        xyz="0 0 0"
        rpy="0 0 0" />
      <geometry>
        <mesh
          filename="package://aws_amr_description/meshes/RR_wheel.STL" />
      </geometry>
      <material
        name="">
        <color
          rgba="0.792156862745098 0.819607843137255 0.933333333333333 1" />
      </material>
    </visual>
    <collision>
      <origin
        xyz="0 0 0"
        rpy="0 0 0" />
      <geometry>
        <mesh
          filename="package://aws_amr_description/meshes/RR_wheel.STL" />
      </geometry>
    </collision>
  </link>
  <joint
    name="RR_wheel_joint"
    type="continuous">
    <origin
      xyz="0.0305792315732384 -0.00142759647720375 -0.12019804241591"
      rpy="1.57079632679489 0 1.49551463375334" />
    <parent
      link="RR_steering_link" />
    <child
      link="RR_wheel" />
    <axis
      xyz="0 0 -1" />
  </joint>
</robot>