<?xml version="1.0" encoding="utf-8"?>
<!-- This URDF was automatically created by SolidWorks to URDF Exporter! Originally created by Stephen Brawner (brawner@gmail.com) 
     Commit Version: 1.6.0-4-g7f85cfe  Build Version: 1.6.7995.38578
     For more information, please see http://wiki.ros.org/sw_urdf_exporter -->
<robot
  name="ODR_Description">
  <link
    name="baseFootprint_link">
    <inertial>
      <origin
        xyz="5.5511E-17 -1.1102E-16 -0.0165"
        rpy="0 0 0" />
      <mass
        value="17.447" />
      <inertia
        ixx="0.56408"
        ixy="-3.2206E-17"
        ixz="1.5967E-19"
        iyy="1.052"
        iyz="7.7457E-34"
        izz="1.613" />
    </inertial>
    <visual>
      <origin
        xyz="0 0 0"
        rpy="0 0 0" />
      <geometry>
        <mesh
          filename="package://ODR_Description/meshes/baseFootprint_link.STL" />
      </geometry>
      <material
        name="">
        <color
          rgba="0.79216 0.81961 0.93333 1" />
      </material>
    </visual>
    <collision>
      <origin
        xyz="0 0 0"
        rpy="0 0 0" />
      <geometry>
        <mesh
          filename="package://ODR_Description/meshes/baseFootprint_link.STL" />
      </geometry>
    </collision>
  </link>
  <link
    name="Base_Link">
    <inertial>
      <origin
        xyz="-0.036174 0.0010579 0.58209"
        rpy="0 0 0" />
      <mass
        value="38.584" />
      <inertia
        ixx="1.1244"
        ixy="-1.233E-06"
        ixz="0.072187"
        iyy="1.942"
        iyz="1.2498E-05"
        izz="2.7197" />
    </inertial>
    <visual>
      <origin
        xyz="0 0 0"
        rpy="0 0 0" />
      <geometry>
        <mesh
          filename="package://ODR_Description/meshes/Base_Link.STL" />
      </geometry>
      <material
        name="">
        <color
          rgba="0.79216 0.81961 0.93333 1" />
      </material>
    </visual>
    <collision>
      <origin
        xyz="0 0 0"
        rpy="0 0 0" />
      <geometry>
        <mesh
          filename="package://ODR_Description/meshes/Base_Link.STL" />
      </geometry>
    </collision>
  </link>
  <joint
    name="Basefootprint_joint"
    type="planar">
    <origin
      xyz="0 0 0.089894"
      rpy="0 0 0" />
    <parent
      link="baseFootprint_link" />
    <child
      link="Base_Link" />
    <axis
      xyz="0 0 0" />
  </joint>
  <link
    name="FL_Link">
    <inertial>
      <origin
        xyz="-0.047555 0.0022762 -0.067761"
        rpy="0 0 0" />
      <mass
        value="0.21503" />
      <inertia
        ixx="0.00019795"
        ixy="-1.3335E-05"
        ixz="-3.351E-05"
        iyy="0.00019983"
        iyz="-2.8177E-05"
        izz="0.00016954" />
    </inertial>
    <visual>
      <origin
        xyz="0 0 0"
        rpy="0 0 0" />
      <geometry>
        <mesh
          filename="package://ODR_Description/meshes/FL_Link.STL" />
      </geometry>
      <material
        name="">
        <color
          rgba="0.79216 0.81961 0.93333 1" />
      </material>
    </visual>
    <collision>
      <origin
        xyz="0 0 0"
        rpy="0 0 0" />
      <geometry>
        <mesh
          filename="package://ODR_Description/meshes/FL_Link.STL" />
      </geometry>
    </collision>
  </link>
  <joint
    name="FL_joint"
    type="revolute">
    <origin
      xyz="-0.29 -0.24 0.1095"
      rpy="0 0 -1.5708" />
    <parent
      link="Base_Link" />
    <child
      link="FL_Link" />
    <axis
      xyz="0 0 1" />
    <limit
      lower="0"
      upper="0"
      effort="0"
      velocity="0" />
  </joint>
  <link
    name="FL_Wheel_Link">
    <inertial>
      <origin
        xyz="7.27157419946889E-06 -1.75839232063879E-10 -0.029854500735608"
        rpy="0 0 0" />
      <mass
        value="0.958023999361774" />
      <inertia
        ixx="0.00158540696073118"
        ixy="-1.05721590858015E-11"
        ixz="-3.83262445164655E-07"
        iyy="0.0015853725682639"
        iyz="-1.10489654833271E-12"
        izz="0.00270273970152626" />
    </inertial>
    <visual>
      <origin
        xyz="0 0 0"
        rpy="0 0 0" />
      <geometry>
        <mesh
          filename="package://ODR_Description/meshes/FL_Wheel_Link.STL" />
      </geometry>
      <material
        name="">
        <color
          rgba="0.792156862745098 0.819607843137255 0.933333333333333 1" />
      </material>
    </visual>
    <collision>
      <origin
        xyz="0 0 0"
        rpy="0 0 0" />
      <geometry>
        <mesh
          filename="package://ODR_Description/meshes/FL_Wheel_Link.STL" />
      </geometry>
    </collision>
  </link>
  <joint
    name="LF_Wheel_joint"
    type="continuous">
    <origin
      xyz="-0.0306 -0.00087633 -0.1202"
      rpy="-1.5708 1.4835 1.5708" />
    <parent
      link="FL_Link" />
    <child
      link="FL_Wheel_Link" />
    <axis
      xyz="0 0 -1" />
  </joint>
  <link
    name="FR_Link">
    <inertial>
      <origin
        xyz="-0.047555 -0.0023382 -0.067761"
        rpy="0 0 0" />
      <mass
        value="0.21503" />
      <inertia
        ixx="0.00019795"
        ixy="1.3311E-05"
        ixz="-3.351E-05"
        iyy="0.00019983"
        iyz="2.8228E-05"
        izz="0.00016954" />
    </inertial>
    <visual>
      <origin
        xyz="0 0 0"
        rpy="0 0 0" />
      <geometry>
        <mesh
          filename="package://ODR_Description/meshes/FR_Link.STL" />
      </geometry>
      <material
        name="">
        <color
          rgba="0.79216 0.81961 0.93333 1" />
      </material>
    </visual>
    <collision>
      <origin
        xyz="0 0 0"
        rpy="0 0 0" />
      <geometry>
        <mesh
          filename="package://ODR_Description/meshes/FR_Link.STL" />
      </geometry>
    </collision>
  </link>
  <joint
    name="FR_joint"
    type="revolute">
    <origin
      xyz="-0.29 0.24 0.1095"
      rpy="0 0 1.5729" />
    <parent
      link="Base_Link" />
    <child
      link="FR_Link" />
    <axis
      xyz="0 0 1" />
    <limit
      lower="0"
      upper="0"
      effort="0"
      velocity="0" />
  </joint>
  <link
    name="FR_Wheel_Link">
    <inertial>
      <origin
        xyz="7.27148910576597E-06 -1.1591219650775E-10 -0.0298545024574719"
        rpy="0 0 0" />
      <mass
        value="0.958024021287255" />
      <inertia
        ixx="0.00158540696974951"
        ixy="-1.05122302310526E-11"
        ixz="-3.83261213961359E-07"
        iyy="0.00158537257740761"
        iyz="-2.21095193519486E-12"
        izz="0.00270273980637586" />
    </inertial>
    <visual>
      <origin
        xyz="0 0 0"
        rpy="0 0 0" />
      <geometry>
        <mesh
          filename="package://ODR_Description/meshes/FR_Wheel_Link.STL" />
      </geometry>
      <material
        name="">
        <color
          rgba="0.792156862745098 0.819607843137255 0.933333333333333 1" />
      </material>
    </visual>
    <collision>
      <origin
        xyz="0 0 0"
        rpy="0 0 0" />
      <geometry>
        <mesh
          filename="package://ODR_Description/meshes/FR_Wheel_Link.STL" />
      </geometry>
    </collision>
  </link>
  <joint
    name="FR_Wheel_joint"
    type="revolute">
    <origin
      xyz="-0.0306 0.00087633 -0.1202"
      rpy="-1.5708 -0.76932 1.5708" />
    <parent
      link="FR_Link" />
    <child
      link="FR_Wheel_Link" />
    <axis
      xyz="0 0 1" />
    <limit
      lower="0"
      upper="0"
      effort="0"
      velocity="0" />
  </joint>
  <link
    name="RL_Link">
    <inertial>
      <origin
        xyz="-0.0475554829926358 -0.00233820854351929 -0.0677612873132223"
        rpy="0 0 0" />
      <mass
        value="0.215025508463833" />
      <inertia
        ixx="0.000197950657899495"
        ixy="1.33114292440054E-05"
        ixz="-3.35101036356306E-05"
        iyy="0.000199828110503897"
        iyz="2.82281827993179E-05"
        izz="0.000169542871282228" />
    </inertial>
    <visual>
      <origin
        xyz="0 0 0"
        rpy="0 0 0" />
      <geometry>
        <mesh
          filename="package://ODR_Description/meshes/RL_Link.STL" />
      </geometry>
      <material
        name="">
        <color
          rgba="0.792156862745098 0.819607843137255 0.933333333333333 1" />
      </material>
    </visual>
    <collision>
      <origin
        xyz="0 0 0"
        rpy="0 0 0" />
      <geometry>
        <mesh
          filename="package://ODR_Description/meshes/RL_Link.STL" />
      </geometry>
    </collision>
  </link>
  <joint
    name="RL_joint"
    type="revolute">
    <origin
      xyz="0.29 -0.24 0.1095"
      rpy="0 0 -1.4052" />
    <parent
      link="Base_Link" />
    <child
      link="RL_Link" />
    <axis
      xyz="0 0 1" />
    <limit
      lower="0"
      upper="0"
      effort="0"
      velocity="0" />
  </joint>
  <link
    name="RL_Wheel_Link">
    <inertial>
      <origin
        xyz="7.2793780465652E-06 -4.18713309857655E-09 -0.0298544966898272"
        rpy="0 0 0" />
      <mass
        value="0.958023987688636" />
      <inertia
        ixx="0.00158540694835643"
        ixy="-3.77768367353806E-11"
        ixz="-3.83124775562562E-07"
        iyy="0.00158537249628559"
        iyz="3.5307860605236E-10"
        izz="0.0027027397868836" />
    </inertial>
    <visual>
      <origin
        xyz="0 0 0"
        rpy="0 0 0" />
      <geometry>
        <mesh
          filename="package://ODR_Description/meshes/RL_Wheel_Link.STL" />
      </geometry>
      <material
        name="">
        <color
          rgba="0.792156862745098 0.819607843137255 0.933333333333333 1" />
      </material>
    </visual>
    <collision>
      <origin
        xyz="0 0 0"
        rpy="0 0 0" />
      <geometry>
        <mesh
          filename="package://ODR_Description/meshes/RL_Wheel_Link.STL" />
      </geometry>
    </collision>
  </link>
  <joint
    name="RL_Wheel_joint"
    type="revolute">
    <origin
      xyz="-0.0306 0.00087633 -0.1202"
      rpy="1.5708 0.25378 -1.5708" />
    <parent
      link="RL_Link" />
    <child
      link="RL_Wheel_Link" />
    <axis
      xyz="0 0 1" />
    <limit
      lower="0"
      upper="0"
      effort="0"
      velocity="0" />
  </joint>
  <link
    name="RR_Link">
    <inertial>
      <origin
        xyz="-0.0475554754330576 0.0022761607665106 -0.0677613704674685"
        rpy="0 0 0" />
      <mass
        value="0.215025526597524" />
      <inertia
        ixx="0.000197950653561478"
        ixy="-1.33354491574847E-05"
        ixz="-3.35101244358478E-05"
        iyy="0.000199827976556842"
        iyz="-2.81773500824485E-05"
        izz="0.000169543008680782" />
    </inertial>
    <visual>
      <origin
        xyz="0 0 0"
        rpy="0 0 0" />
      <geometry>
        <mesh
          filename="package://ODR_Description/meshes/RR_Link.STL" />
      </geometry>
      <material
        name="">
        <color
          rgba="0.792156862745098 0.819607843137255 0.933333333333333 1" />
      </material>
    </visual>
    <collision>
      <origin
        xyz="0 0 0"
        rpy="0 0 0" />
      <geometry>
        <mesh
          filename="package://ODR_Description/meshes/RR_Link.STL" />
      </geometry>
    </collision>
  </link>
  <joint
    name="RR_joint"
    type="revolute">
    <origin
      xyz="0.29 0.24 0.1095"
      rpy="0 0 1.4868" />
    <parent
      link="Base_Link" />
    <child
      link="RR_Link" />
    <axis
      xyz="0 0 1" />
    <limit
      lower="0"
      upper="0"
      effort="0"
      velocity="0" />
  </joint>
  <link
    name="RR_Wheel_Link">
    <inertial>
      <origin
        xyz="7.27624908103408E-06 6.957644599348E-10 -0.0298544942168065"
        rpy="0 0 0" />
      <mass
        value="0.958024073701802" />
      <inertia
        ixx="0.00158540700210959"
        ixy="3.39989887689744E-11"
        ixz="-3.83108836539905E-07"
        iyy="0.00158537272992388"
        iyz="3.27083678219858E-10"
        izz="0.00270274016824093" />
    </inertial>
    <visual>
      <origin
        xyz="0 0 0"
        rpy="0 0 0" />
      <geometry>
        <mesh
          filename="package://ODR_Description/meshes/RR_Wheel_Link.STL" />
      </geometry>
      <material
        name="">
        <color
          rgba="0.792156862745098 0.819607843137255 0.933333333333333 1" />
      </material>
    </visual>
    <collision>
      <origin
        xyz="0 0 0"
        rpy="0 0 0" />
      <geometry>
        <mesh
          filename="package://ODR_Description/meshes/RR_Wheel_Link.STL" />
      </geometry>
    </collision>
  </link>
  <joint
    name="RR_Wheel_joint"
    type="revolute">
    <origin
      xyz="-0.0306 -0.00087633 -0.1202"
      rpy="-1.5708 0 1.5708" />
    <parent
      link="RR_Link" />
    <child
      link="RR_Wheel_Link" />
    <axis
      xyz="0 0 -1" />
    <limit
      lower="0"
      upper="0"
      effort="0"
      velocity="0" />
  </joint>
</robot>