<?xml version="1.0" encoding="utf-8"?>
<!-- This URDF was automatically created by SolidWorks to URDF Exporter! Originally created by Stephen Brawner (brawner@gmail.com) 
     Commit Version: 1.6.0-4-g7f85cfe  Build Version: 1.6.7995.38578
     For more information, please see http://wiki.ros.org/sw_urdf_exporter -->
<robot
  name="robot assy.SLDASM">
  <link
    name="basefootprint_link">
    <inertial>
      <origin
        xyz="0 1.11022302462516E-16 -0.0165"
        rpy="0 0 0" />
      <mass
        value="40.12833" />
      <inertia
        ixx="2.41961604813898"
        ixy="0.00979349757253783"
        ixz="-3.46348297131225E-19"
        iyy="1.29747784781603"
        iyz="2.94246210047988E-16"
        izz="3.70981060406001" />
    </inertial>
    <visual>
      <origin
        xyz="0 0 0"
        rpy="0 0 0" />
      <geometry>
        <mesh
          filename="package://robot assy.SLDASM/meshes/basefootprint_link.STL" />
      </geometry>
      <material
        name="">
        <color
          rgba="0.988235294117647 0.984313725490196 1 1" />
      </material>
    </visual>
    <collision>
      <origin
        xyz="0 0 0"
        rpy="0 0 0" />
      <geometry>
        <mesh
          filename="package://robot assy.SLDASM/meshes/basefootprint_link.STL" />
      </geometry>
    </collision>
  </link>
  <link
    name="base_link">
    <inertial>
      <origin
        xyz="-0.00164219166090096 -0.0361894519725367 0.582086232959336"
        rpy="0 0 0" />
      <mass
        value="38.5841907210089" />
      <inertia
        ixx="1.94197264059665"
        ixy="0.00713596425149988"
        ixz="-0.000642438598698668"
        iyy="1.12447543859211"
        iyz="0.0721839356855261"
        izz="2.71974540999521" />
    </inertial>
    <visual>
      <origin
        xyz="0 0 0"
        rpy="0 0 0" />
      <geometry>
        <mesh
          filename="package://robot assy.SLDASM/meshes/base_link.STL" />
      </geometry>
      <material
        name="">
        <color
          rgba="0.792156862745098 0.819607843137255 0.933333333333333 1" />
      </material>
    </visual>
    <collision>
      <origin
        xyz="0 0 0"
        rpy="0 0 0" />
      <geometry>
        <mesh
          filename="package://robot assy.SLDASM/meshes/base_link.STL" />
      </geometry>
    </collision>
  </link>
  <joint
    name="base_joint"
    type="fixed">
    <origin
      xyz="0.00089997 0 0.089894"
      rpy="0 0 0" />
    <parent
      link="basefootprint_link" />
    <child
      link="base_link" />
    <axis
      xyz="0 0 0" />
  </joint>
  <link
    name="FL_steering_link">
    <inertial>
      <origin
        xyz="-0.0475735313962518 0.00186107687732573 -0.0677613689716037"
        rpy="0 0 0" />
      <mass
        value="0.215025529188034" />
      <inertia
        ixx="0.000198183542175169"
        ixy="-1.3349793725885E-05"
        ixz="-3.32629600062834E-05"
        iyy="0.000199595091165542"
        iyz="-2.84687052890827E-05"
        izz="0.0001695430097707" />
    </inertial>
    <visual>
      <origin
        xyz="0 0 0"
        rpy="0 0 0" />
      <geometry>
        <mesh
          filename="package://robot assy.SLDASM/meshes/FL_steering_link.STL" />
      </geometry>
      <material
        name="">
        <color
          rgba="0.792156862745098 0.819607843137255 0.933333333333333 1" />
      </material>
    </visual>
    <collision>
      <origin
        xyz="0 0 0"
        rpy="0 0 0" />
      <geometry>
        <mesh
          filename="package://robot assy.SLDASM/meshes/FL_steering_link.STL" />
      </geometry>
    </collision>
  </link>
  <joint
    name="FL_steering_joint"
    type="continuous">
    <origin
      xyz="0.241621591099171 -0.287902443050945 0.1095"
      rpy="0 0 0" />
    <parent
      link="base_link" />
    <child
      link="FL_steering_link" />
    <axis
      xyz="0 0 1" />
  </joint>
  <link
    name="FL_wheel">
    <inertial>
      <origin
        xyz="-6.33164459307167E-07 7.24319215807123E-06 0.0298545011765312"
        rpy="0 0 0" />
      <mass
        value="0.958024018560993" />
      <inertia
        ixx="0.00158537287142923"
        ixy="-2.9584644178286E-09"
        ixz="-3.34102631120875E-08"
        iyy="0.00158540670170445"
        iyz="3.81832211648325E-07"
        izz="0.00270273979063561" />
    </inertial>
    <visual>
      <origin
        xyz="0 0 0"
        rpy="0 0 0" />
      <geometry>
        <mesh
          filename="package://robot assy.SLDASM/meshes/FL_wheel.STL" />
      </geometry>
      <material
        name="">
        <color
          rgba="0.792156862745098 0.819607843137255 0.933333333333333 1" />
      </material>
    </visual>
    <collision>
      <origin
        xyz="0 0 0"
        rpy="0 0 0" />
      <geometry>
        <mesh
          filename="package://robot assy.SLDASM/meshes/FL_wheel.STL" />
      </geometry>
    </collision>
  </link>
  <joint
    name="FL_wheel_joint"
    type="continuous">
    <origin
      xyz="-0.0305911790614908 -0.00114332801035 -0.120198042415907"
      rpy="-1.5707963267949 0 -1.56206968053491" />
    <parent
      link="FL_steering_link" />
    <child
      link="FL_wheel" />
    <axis
      xyz="0 0 1" />
  </joint>
  <link
    name="FR_steering_link">
    <inertial>
      <origin
        xyz="0.0475332676644014 0.00275311602446848 -0.0677612853470633"
        rpy="0 0 0" />
      <mass
        value="0.215025528947219" />
      <inertia
        ixx="0.000197718490479999"
        ixy="1.32930141918077E-05"
        ixz="3.37551609187015E-05"
        iyy="0.000200060279861215"
        iyz="-2.79346804830956E-05"
        izz="0.000169542872761945" />
    </inertial>
    <visual>
      <origin
        xyz="0 0 0"
        rpy="0 0 0" />
      <geometry>
        <mesh
          filename="package://robot assy.SLDASM/meshes/FR_steering_link.STL" />
      </geometry>
      <material
        name="">
        <color
          rgba="0.792156862745098 0.819607843137255 0.933333333333333 1" />
      </material>
    </visual>
    <collision>
      <origin
        xyz="0 0 0"
        rpy="0 0 0" />
      <geometry>
        <mesh
          filename="package://robot assy.SLDASM/meshes/FR_steering_link.STL" />
      </geometry>
    </collision>
  </link>
  <joint
    name="FR_steering_joint"
    type="continuous">
    <origin
      xyz="-0.238360131971625 -0.292091180090165 0.1095"
      rpy="0 0 0" />
    <parent
      link="base_link" />
    <child
      link="FR_steering_link" />
    <axis
      xyz="0 0 1" />
  </joint>
  <link
    name="FR_wheel">
    <inertial>
      <origin
        xyz="-7.25632208209426E-06 -5.02980211800064E-07 -0.0298544958122798"
        rpy="0 0 0" />
      <mass
        value="0.958023968371171" />
      <inertia
        ixx="0.0015854067935003"
        ixy="2.35162659253672E-09"
        ixz="3.82180143814828E-07"
        iyy="0.00158537266869454"
        iyz="2.63310496845712E-08"
        izz="0.00270273963326959" />
    </inertial>
    <visual>
      <origin
        xyz="0 0 0"
        rpy="0 0 0" />
      <geometry>
        <mesh
          filename="package://robot assy.SLDASM/meshes/FR_wheel.STL" />
      </geometry>
      <material
        name="">
        <color
          rgba="0.792156862745098 0.819607843137255 0.933333333333333 1" />
      </material>
    </visual>
    <collision>
      <origin
        xyz="0 0 0"
        rpy="0 0 0" />
      <geometry>
        <mesh
          filename="package://robot assy.SLDASM/meshes/FR_wheel.STL" />
      </geometry>
    </collision>
  </link>
  <joint
    name="FR_wheel_joint"
    type="continuous">
    <origin
      xyz="0.0306064737018755 -0.000609264185578828 -0.120198042415909"
      rpy="-1.5707963267949 0 -1.56206968053492" />
    <parent
      link="FR_steering_link" />
    <child
      link="FR_wheel" />
    <axis
      xyz="0 0 -1" />
  </joint>
  <link
    name="RL_steering_link">
    <inertial>
      <origin
        xyz="-0.0475332676644018 -0.0027531160244687 -0.0677612853470547"
        rpy="0 0 0" />
      <mass
        value="0.215025528947221" />
      <inertia
        ixx="0.000197718490480003"
        ixy="1.32930141918064E-05"
        ixz="-3.37551609187014E-05"
        iyy="0.000200060279861221"
        iyz="2.79346804830953E-05"
        izz="0.000169542872761945" />
    </inertial>
    <visual>
      <origin
        xyz="0 0 0"
        rpy="0 0 0" />
      <geometry>
        <mesh
          filename="package://robot assy.SLDASM/meshes/RL_steering_link.STL" />
      </geometry>
      <material
        name="">
        <color
          rgba="0.792156862745098 0.819607843137255 0.933333333333333 1" />
      </material>
    </visual>
    <collision>
      <origin
        xyz="0 0 0"
        rpy="0 0 0" />
      <geometry>
        <mesh
          filename="package://robot assy.SLDASM/meshes/RL_steering_link.STL" />
      </geometry>
    </collision>
  </link>
  <joint
    name="RL_steering_joint"
    type="continuous">
    <origin
      xyz="0.236560200510107 0.292075472326287 0.109500000000001"
      rpy="0 0 0" />
    <parent
      link="base_link" />
    <child
      link="RL_steering_link" />
    <axis
      xyz="0 0 1" />
  </joint>
  <link
    name="RL_wheel">
    <inertial>
      <origin
        xyz="7.27159198632421E-06 -6.51543927837617E-08 0.0298545007582798"
        rpy="0 0 0" />
      <mass
        value="0.95802401302459" />
      <inertia
        ixx="0.00158540700752927"
        ixy="-2.83636381736739E-10"
        ixz="3.8324607122713E-07"
        iyy="0.00158537256099176"
        iyz="-3.41343993328251E-09"
        izz="0.00270273976518547" />
    </inertial>
    <visual>
      <origin
        xyz="0 0 0"
        rpy="0 0 0" />
      <geometry>
        <mesh
          filename="package://robot assy.SLDASM/meshes/RL_wheel.STL" />
      </geometry>
      <material
        name="">
        <color
          rgba="0.792156862745098 0.819607843137255 0.933333333333333 1" />
      </material>
    </visual>
    <collision>
      <origin
        xyz="0 0 0"
        rpy="0 0 0" />
      <geometry>
        <mesh
          filename="package://robot assy.SLDASM/meshes/RL_wheel.STL" />
      </geometry>
    </collision>
  </link>
  <joint
    name="RL_wheel_joint"
    type="continuous">
    <origin
      xyz="-0.0306064737018754 0.000609264185579161 -0.120198042415909"
      rpy="-1.57079632679489 0 -1.56206968053493" />
    <parent
      link="RL_steering_link" />
    <child
      link="RL_wheel" />
    <axis
      xyz="0 0 1" />
  </joint>
  <link
    name="RR_steering_link">
    <inertial>
      <origin
        xyz="0.0475735313962523 -0.00186107687732562 -0.067761368971604"
        rpy="0 0 0" />
      <mass
        value="0.215025529188032" />
      <inertia
        ixx="0.000198183542170154"
        ixy="-1.33497937261377E-05"
        ixz="3.32629600070807E-05"
        iyy="0.000199595091161019"
        iyz="2.84687052871704E-05"
        izz="0.000169543009769997" />
    </inertial>
    <visual>
      <origin
        xyz="0 0 0"
        rpy="0 0 0" />
      <geometry>
        <mesh
          filename="package://robot assy.SLDASM/meshes/RR_steering_link.STL" />
      </geometry>
      <material
        name="">
        <color
          rgba="0.792156862745098 0.819607843137255 0.933333333333333 1" />
      </material>
    </visual>
    <collision>
      <origin
        xyz="0 0 0"
        rpy="0 0 0" />
      <geometry>
        <mesh
          filename="package://robot assy.SLDASM/meshes/RR_steering_link.STL" />
      </geometry>
    </collision>
  </link>
  <joint
    name="RR_steering_joint"
    type="continuous">
    <origin
      xyz="-0.24342152256069 0.287886735287059 0.109500000000002"
      rpy="0 0 0" />
    <parent
      link="base_link" />
    <child
      link="RR_steering_link" />
    <axis
      xyz="0 0 1" />
  </joint>
  <link
    name="RR_wheel">
    <inertial>
      <origin
        xyz="7.20462982484182E-06 9.68505780116202E-07 -0.0298544958076753"
        rpy="0 0 0" />
      <mass
        value="0.958023969041703" />
      <inertia
        ixx="0.00158540634795059"
        ixy="4.53161844102951E-09"
        ixz="-3.79997418333319E-07"
        iyy="0.00158537311547568"
        iyz="-5.12644367348954E-08"
        izz="0.00270273963443473" />
    </inertial>
    <visual>
      <origin
        xyz="0 0 0"
        rpy="0 0 0" />
      <geometry>
        <mesh
          filename="package://robot assy.SLDASM/meshes/RR_wheel.STL" />
      </geometry>
      <material
        name="">
        <color
          rgba="0.792156862745098 0.819607843137255 0.933333333333333 1" />
      </material>
    </visual>
    <collision>
      <origin
        xyz="0 0 0"
        rpy="0 0 0" />
      <geometry>
        <mesh
          filename="package://robot assy.SLDASM/meshes/RR_wheel.STL" />
      </geometry>
    </collision>
  </link>
  <joint
    name="RR_wheel_joint"
    type="continuous">
    <origin
      xyz="0.0305911790614906 0.00114332801034964 -0.12019804241591"
      rpy="-1.5707963267949 0 -1.56206968053492" />
    <parent
      link="RR_steering_link" />
    <child
      link="RR_wheel" />
    <axis
      xyz="0 0 -1" />
  </joint>
</robot>